[2024-07-16 06:59:50,105] {taskinstance.py:1032} INFO - Dependencies all met for <TaskInstance: load_stg_to_dds.load_data_dds manual__2024-07-16T06:59:49.211030+00:00 [queued]>
[2024-07-16 06:59:50,116] {taskinstance.py:1032} INFO - Dependencies all met for <TaskInstance: load_stg_to_dds.load_data_dds manual__2024-07-16T06:59:49.211030+00:00 [queued]>
[2024-07-16 06:59:50,117] {taskinstance.py:1238} INFO - 
--------------------------------------------------------------------------------
[2024-07-16 06:59:50,118] {taskinstance.py:1239} INFO - Starting attempt 1 of 1
[2024-07-16 06:59:50,118] {taskinstance.py:1240} INFO - 
--------------------------------------------------------------------------------
[2024-07-16 06:59:50,129] {taskinstance.py:1259} INFO - Executing <Task(_PythonDecoratedOperator): load_data_dds> on 2024-07-16 06:59:49.211030+00:00
[2024-07-16 06:59:50,133] {standard_task_runner.py:52} INFO - Started process 18392 to run task
[2024-07-16 06:59:50,136] {standard_task_runner.py:76} INFO - Running: ['airflow', 'tasks', 'run', 'load_stg_to_dds', 'load_data_dds', 'manual__2024-07-16T06:59:49.211030+00:00', '--job-id', '32', '--raw', '--subdir', 'DAGS_FOLDER/load_stg_to_dds.py', '--cfg-path', '/tmp/tmp68j1t2b7', '--error-file', '/tmp/tmpbjhtd7ro']
[2024-07-16 06:59:50,139] {standard_task_runner.py:77} INFO - Job 32: Subtask load_data_dds
[2024-07-16 06:59:50,221] {logging_mixin.py:109} INFO - Running <TaskInstance: load_stg_to_dds.load_data_dds manual__2024-07-16T06:59:49.211030+00:00 [running]> on host 676d07ac814a
[2024-07-16 06:59:50,292] {taskinstance.py:1426} INFO - Exporting the following env vars:
AIRFLOW_CTX_DAG_OWNER=airflow
AIRFLOW_CTX_DAG_ID=load_stg_to_dds
AIRFLOW_CTX_TASK_ID=load_data_dds
AIRFLOW_CTX_EXECUTION_DATE=2024-07-16T06:59:49.211030+00:00
AIRFLOW_CTX_DAG_RUN_ID=manual__2024-07-16T06:59:49.211030+00:00
[2024-07-16 06:59:50,392] {taskinstance.py:1700} ERROR - Task failed with exception
Traceback (most recent call last):
  File "/home/airflow/.local/lib/python3.6/site-packages/airflow/models/taskinstance.py", line 1329, in _run_raw_task
    self._execute_task_with_callbacks(context)
  File "/home/airflow/.local/lib/python3.6/site-packages/airflow/models/taskinstance.py", line 1455, in _execute_task_with_callbacks
    result = self._execute_task(context, self.task)
  File "/home/airflow/.local/lib/python3.6/site-packages/airflow/models/taskinstance.py", line 1511, in _execute_task
    result = execute_callable(context=context)
  File "/home/airflow/.local/lib/python3.6/site-packages/airflow/decorators/base.py", line 134, in execute
    return_value = super().execute(context)
  File "/home/airflow/.local/lib/python3.6/site-packages/airflow/operators/python.py", line 174, in execute
    return_value = self.execute_callable()
  File "/home/airflow/.local/lib/python3.6/site-packages/airflow/operators/python.py", line 185, in execute_callable
    return self.python_callable(*self.op_args, **self.op_kwargs)
  File "/opt/airflow/dags/load_stg_to_dds.py", line 163, in load_data_dds
    source_conn.commit()
NameError: name 'source_conn' is not defined
[2024-07-16 06:59:50,413] {taskinstance.py:1277} INFO - Marking task as FAILED. dag_id=load_stg_to_dds, task_id=load_data_dds, execution_date=20240716T065949, start_date=20240716T065950, end_date=20240716T065950
[2024-07-16 06:59:50,427] {standard_task_runner.py:92} ERROR - Failed to execute job 32 for task load_data_dds
Traceback (most recent call last):
  File "/home/airflow/.local/lib/python3.6/site-packages/airflow/task/task_runner/standard_task_runner.py", line 85, in _start_by_fork
    args.func(args, dag=self.dag)
  File "/home/airflow/.local/lib/python3.6/site-packages/airflow/cli/cli_parser.py", line 48, in command
    return func(*args, **kwargs)
  File "/home/airflow/.local/lib/python3.6/site-packages/airflow/utils/cli.py", line 92, in wrapper
    return f(*args, **kwargs)
  File "/home/airflow/.local/lib/python3.6/site-packages/airflow/cli/commands/task_command.py", line 298, in task_run
    _run_task_by_selected_method(args, dag, ti)
  File "/home/airflow/.local/lib/python3.6/site-packages/airflow/cli/commands/task_command.py", line 107, in _run_task_by_selected_method
    _run_raw_task(args, ti)
  File "/home/airflow/.local/lib/python3.6/site-packages/airflow/cli/commands/task_command.py", line 184, in _run_raw_task
    error_file=args.error_file,
  File "/home/airflow/.local/lib/python3.6/site-packages/airflow/utils/session.py", line 70, in wrapper
    return func(*args, session=session, **kwargs)
  File "/home/airflow/.local/lib/python3.6/site-packages/airflow/models/taskinstance.py", line 1329, in _run_raw_task
    self._execute_task_with_callbacks(context)
  File "/home/airflow/.local/lib/python3.6/site-packages/airflow/models/taskinstance.py", line 1455, in _execute_task_with_callbacks
    result = self._execute_task(context, self.task)
  File "/home/airflow/.local/lib/python3.6/site-packages/airflow/models/taskinstance.py", line 1511, in _execute_task
    result = execute_callable(context=context)
  File "/home/airflow/.local/lib/python3.6/site-packages/airflow/decorators/base.py", line 134, in execute
    return_value = super().execute(context)
  File "/home/airflow/.local/lib/python3.6/site-packages/airflow/operators/python.py", line 174, in execute
    return_value = self.execute_callable()
  File "/home/airflow/.local/lib/python3.6/site-packages/airflow/operators/python.py", line 185, in execute_callable
    return self.python_callable(*self.op_args, **self.op_kwargs)
  File "/opt/airflow/dags/load_stg_to_dds.py", line 163, in load_data_dds
    source_conn.commit()
NameError: name 'source_conn' is not defined
[2024-07-16 06:59:50,439] {local_task_job.py:154} INFO - Task exited with return code 1
[2024-07-16 06:59:50,519] {local_task_job.py:264} INFO - 0 downstream tasks scheduled from follow-on schedule check
