[2024-07-15 22:50:27,712] {taskinstance.py:1032} INFO - Dependencies all met for <TaskInstance: load_stg_to_dds.migrate_data scheduled__2024-07-15T22:50:25.012023+00:00 [queued]>
[2024-07-15 22:50:27,724] {taskinstance.py:1032} INFO - Dependencies all met for <TaskInstance: load_stg_to_dds.migrate_data scheduled__2024-07-15T22:50:25.012023+00:00 [queued]>
[2024-07-15 22:50:27,724] {taskinstance.py:1238} INFO - 
--------------------------------------------------------------------------------
[2024-07-15 22:50:27,725] {taskinstance.py:1239} INFO - Starting attempt 1 of 1
[2024-07-15 22:50:27,725] {taskinstance.py:1240} INFO - 
--------------------------------------------------------------------------------
[2024-07-15 22:50:27,736] {taskinstance.py:1259} INFO - Executing <Task(_PythonDecoratedOperator): migrate_data> on 2024-07-15 22:50:25.012023+00:00
[2024-07-15 22:50:27,740] {standard_task_runner.py:52} INFO - Started process 14422 to run task
[2024-07-15 22:50:27,743] {standard_task_runner.py:76} INFO - Running: ['airflow', 'tasks', 'run', 'load_stg_to_dds', 'migrate_data', 'scheduled__2024-07-15T22:50:25.012023+00:00', '--job-id', '24', '--raw', '--subdir', 'DAGS_FOLDER/load_stg_to_dds.py', '--cfg-path', '/tmp/tmp0g212d31', '--error-file', '/tmp/tmpvfipfydi']
[2024-07-15 22:50:27,747] {standard_task_runner.py:77} INFO - Job 24: Subtask migrate_data
[2024-07-15 22:50:27,843] {logging_mixin.py:109} INFO - Running <TaskInstance: load_stg_to_dds.migrate_data scheduled__2024-07-15T22:50:25.012023+00:00 [running]> on host 676d07ac814a
[2024-07-15 22:50:27,914] {taskinstance.py:1426} INFO - Exporting the following env vars:
AIRFLOW_CTX_DAG_OWNER=airflow
AIRFLOW_CTX_DAG_ID=load_stg_to_dds
AIRFLOW_CTX_TASK_ID=migrate_data
AIRFLOW_CTX_EXECUTION_DATE=2024-07-15T22:50:25.012023+00:00
AIRFLOW_CTX_DAG_RUN_ID=scheduled__2024-07-15T22:50:25.012023+00:00
[2024-07-15 22:50:27,943] {taskinstance.py:1700} ERROR - Task failed with exception
Traceback (most recent call last):
  File "/home/airflow/.local/lib/python3.6/site-packages/airflow/models/taskinstance.py", line 1329, in _run_raw_task
    self._execute_task_with_callbacks(context)
  File "/home/airflow/.local/lib/python3.6/site-packages/airflow/models/taskinstance.py", line 1455, in _execute_task_with_callbacks
    result = self._execute_task(context, self.task)
  File "/home/airflow/.local/lib/python3.6/site-packages/airflow/models/taskinstance.py", line 1511, in _execute_task
    result = execute_callable(context=context)
  File "/home/airflow/.local/lib/python3.6/site-packages/airflow/decorators/base.py", line 134, in execute
    return_value = super().execute(context)
  File "/home/airflow/.local/lib/python3.6/site-packages/airflow/operators/python.py", line 174, in execute
    return_value = self.execute_callable()
  File "/home/airflow/.local/lib/python3.6/site-packages/airflow/operators/python.py", line 185, in execute_callable
    return self.python_callable(*self.op_args, **self.op_kwargs)
  File "/opt/airflow/dags/load_stg_to_dds.py", line 34, in migrate_data
    source_cursor.execute("SELECT * FROM peoples")
  File "/home/airflow/.local/lib/python3.6/site-packages/vertica_python/vertica/cursor.py", line 238, in execute
    self._execute_simple_query(operation)
  File "/home/airflow/.local/lib/python3.6/site-packages/vertica_python/vertica/cursor.py", line 660, in _execute_simple_query
    raise errors.QueryError.from_error_response(self._message, query)
vertica_python.errors.MissingRelation: Severity: ERROR, Message: Relation "peoples" does not exist, Sqlstate: 42V01, Routine: throwRelationDoesNotExist, File: /data/jenkins/workspace/RE-ReleaseBuilds/RE-Miner/server/vertica/Catalog/CatalogLookup.cpp, Line: 4331, Error Code: 4566, SQL: 'SELECT * FROM peoples'
[2024-07-15 22:50:27,960] {taskinstance.py:1277} INFO - Marking task as FAILED. dag_id=load_stg_to_dds, task_id=migrate_data, execution_date=20240715T225025, start_date=20240715T225027, end_date=20240715T225027
[2024-07-15 22:50:27,973] {standard_task_runner.py:92} ERROR - Failed to execute job 24 for task migrate_data
Traceback (most recent call last):
  File "/home/airflow/.local/lib/python3.6/site-packages/airflow/task/task_runner/standard_task_runner.py", line 85, in _start_by_fork
    args.func(args, dag=self.dag)
  File "/home/airflow/.local/lib/python3.6/site-packages/airflow/cli/cli_parser.py", line 48, in command
    return func(*args, **kwargs)
  File "/home/airflow/.local/lib/python3.6/site-packages/airflow/utils/cli.py", line 92, in wrapper
    return f(*args, **kwargs)
  File "/home/airflow/.local/lib/python3.6/site-packages/airflow/cli/commands/task_command.py", line 298, in task_run
    _run_task_by_selected_method(args, dag, ti)
  File "/home/airflow/.local/lib/python3.6/site-packages/airflow/cli/commands/task_command.py", line 107, in _run_task_by_selected_method
    _run_raw_task(args, ti)
  File "/home/airflow/.local/lib/python3.6/site-packages/airflow/cli/commands/task_command.py", line 184, in _run_raw_task
    error_file=args.error_file,
  File "/home/airflow/.local/lib/python3.6/site-packages/airflow/utils/session.py", line 70, in wrapper
    return func(*args, session=session, **kwargs)
  File "/home/airflow/.local/lib/python3.6/site-packages/airflow/models/taskinstance.py", line 1329, in _run_raw_task
    self._execute_task_with_callbacks(context)
  File "/home/airflow/.local/lib/python3.6/site-packages/airflow/models/taskinstance.py", line 1455, in _execute_task_with_callbacks
    result = self._execute_task(context, self.task)
  File "/home/airflow/.local/lib/python3.6/site-packages/airflow/models/taskinstance.py", line 1511, in _execute_task
    result = execute_callable(context=context)
  File "/home/airflow/.local/lib/python3.6/site-packages/airflow/decorators/base.py", line 134, in execute
    return_value = super().execute(context)
  File "/home/airflow/.local/lib/python3.6/site-packages/airflow/operators/python.py", line 174, in execute
    return_value = self.execute_callable()
  File "/home/airflow/.local/lib/python3.6/site-packages/airflow/operators/python.py", line 185, in execute_callable
    return self.python_callable(*self.op_args, **self.op_kwargs)
  File "/opt/airflow/dags/load_stg_to_dds.py", line 34, in migrate_data
    source_cursor.execute("SELECT * FROM peoples")
  File "/home/airflow/.local/lib/python3.6/site-packages/vertica_python/vertica/cursor.py", line 238, in execute
    self._execute_simple_query(operation)
  File "/home/airflow/.local/lib/python3.6/site-packages/vertica_python/vertica/cursor.py", line 660, in _execute_simple_query
    raise errors.QueryError.from_error_response(self._message, query)
vertica_python.errors.MissingRelation: Severity: ERROR, Message: Relation "peoples" does not exist, Sqlstate: 42V01, Routine: throwRelationDoesNotExist, File: /data/jenkins/workspace/RE-ReleaseBuilds/RE-Miner/server/vertica/Catalog/CatalogLookup.cpp, Line: 4331, Error Code: 4566, SQL: 'SELECT * FROM peoples'
[2024-07-15 22:50:28,007] {local_task_job.py:154} INFO - Task exited with return code 1
[2024-07-15 22:50:28,046] {local_task_job.py:264} INFO - 0 downstream tasks scheduled from follow-on schedule check
