[2024-08-12 21:50:36,365] {taskinstance.py:1032} INFO - Dependencies all met for <TaskInstance: load_dds_to_cdm.populate_view_table manual__2024-08-12T21:50:33.639850+00:00 [queued]>
[2024-08-12 21:50:36,377] {taskinstance.py:1032} INFO - Dependencies all met for <TaskInstance: load_dds_to_cdm.populate_view_table manual__2024-08-12T21:50:33.639850+00:00 [queued]>
[2024-08-12 21:50:36,377] {taskinstance.py:1238} INFO - 
--------------------------------------------------------------------------------
[2024-08-12 21:50:36,378] {taskinstance.py:1239} INFO - Starting attempt 1 of 1
[2024-08-12 21:50:36,378] {taskinstance.py:1240} INFO - 
--------------------------------------------------------------------------------
[2024-08-12 21:50:36,391] {taskinstance.py:1259} INFO - Executing <Task(_PythonDecoratedOperator): populate_view_table> on 2024-08-12 21:50:33.639850+00:00
[2024-08-12 21:50:36,396] {standard_task_runner.py:52} INFO - Started process 2257 to run task
[2024-08-12 21:50:36,399] {standard_task_runner.py:76} INFO - Running: ['airflow', 'tasks', 'run', 'load_dds_to_cdm', 'populate_view_table', 'manual__2024-08-12T21:50:33.639850+00:00', '--job-id', '66', '--raw', '--subdir', 'DAGS_FOLDER/load_dds_to_cdm.py', '--cfg-path', '/tmp/tmp6s2bt1ia', '--error-file', '/tmp/tmpkssk66wx']
[2024-08-12 21:50:36,403] {standard_task_runner.py:77} INFO - Job 66: Subtask populate_view_table
[2024-08-12 21:50:36,469] {logging_mixin.py:109} INFO - Running <TaskInstance: load_dds_to_cdm.populate_view_table manual__2024-08-12T21:50:33.639850+00:00 [running]> on host 915f51171463
[2024-08-12 21:50:36,554] {taskinstance.py:1426} INFO - Exporting the following env vars:
AIRFLOW_CTX_DAG_OWNER=airflow
AIRFLOW_CTX_DAG_ID=load_dds_to_cdm
AIRFLOW_CTX_TASK_ID=populate_view_table
AIRFLOW_CTX_EXECUTION_DATE=2024-08-12T21:50:33.639850+00:00
AIRFLOW_CTX_DAG_RUN_ID=manual__2024-08-12T21:50:33.639850+00:00
[2024-08-12 21:50:36,563] {taskinstance.py:1700} ERROR - Task failed with exception
Traceback (most recent call last):
  File "/home/airflow/.local/lib/python3.6/site-packages/airflow/models/taskinstance.py", line 1329, in _run_raw_task
    self._execute_task_with_callbacks(context)
  File "/home/airflow/.local/lib/python3.6/site-packages/airflow/models/taskinstance.py", line 1455, in _execute_task_with_callbacks
    result = self._execute_task(context, self.task)
  File "/home/airflow/.local/lib/python3.6/site-packages/airflow/models/taskinstance.py", line 1511, in _execute_task
    result = execute_callable(context=context)
  File "/home/airflow/.local/lib/python3.6/site-packages/airflow/decorators/base.py", line 134, in execute
    return_value = super().execute(context)
  File "/home/airflow/.local/lib/python3.6/site-packages/airflow/operators/python.py", line 174, in execute
    return_value = self.execute_callable()
  File "/home/airflow/.local/lib/python3.6/site-packages/airflow/operators/python.py", line 185, in execute_callable
    return self.python_callable(*self.op_args, **self.op_kwargs)
  File "/opt/airflow/dags/load_dds_to_cdm.py", line 101, in populate_view_table
    cursor.execute(insert_query, {'age_group': row[0], 'user_count': row[1]})
  File "/home/airflow/.local/lib/python3.6/site-packages/vertica_python/vertica/cursor.py", line 238, in execute
    self._execute_simple_query(operation)
  File "/home/airflow/.local/lib/python3.6/site-packages/vertica_python/vertica/cursor.py", line 660, in _execute_simple_query
    raise errors.QueryError.from_error_response(self._message, query)
vertica_python.errors.QueryError: Severity: ERROR, Message: Invalid input syntax for integer: "0-17", Sqlstate: 22V02, Routine: scanint8, File: int8.c, Line: 124, Error Code: 3681, SQL: "             INSERT INTO dm.user_age_groups (age_group, user_count) VALUES (1, '0-17')         "
[2024-08-12 21:50:36,582] {taskinstance.py:1277} INFO - Marking task as FAILED. dag_id=load_dds_to_cdm, task_id=populate_view_table, execution_date=20240812T215033, start_date=20240812T215036, end_date=20240812T215036
[2024-08-12 21:50:36,597] {standard_task_runner.py:92} ERROR - Failed to execute job 66 for task populate_view_table
Traceback (most recent call last):
  File "/home/airflow/.local/lib/python3.6/site-packages/airflow/task/task_runner/standard_task_runner.py", line 85, in _start_by_fork
    args.func(args, dag=self.dag)
  File "/home/airflow/.local/lib/python3.6/site-packages/airflow/cli/cli_parser.py", line 48, in command
    return func(*args, **kwargs)
  File "/home/airflow/.local/lib/python3.6/site-packages/airflow/utils/cli.py", line 92, in wrapper
    return f(*args, **kwargs)
  File "/home/airflow/.local/lib/python3.6/site-packages/airflow/cli/commands/task_command.py", line 298, in task_run
    _run_task_by_selected_method(args, dag, ti)
  File "/home/airflow/.local/lib/python3.6/site-packages/airflow/cli/commands/task_command.py", line 107, in _run_task_by_selected_method
    _run_raw_task(args, ti)
  File "/home/airflow/.local/lib/python3.6/site-packages/airflow/cli/commands/task_command.py", line 184, in _run_raw_task
    error_file=args.error_file,
  File "/home/airflow/.local/lib/python3.6/site-packages/airflow/utils/session.py", line 70, in wrapper
    return func(*args, session=session, **kwargs)
  File "/home/airflow/.local/lib/python3.6/site-packages/airflow/models/taskinstance.py", line 1329, in _run_raw_task
    self._execute_task_with_callbacks(context)
  File "/home/airflow/.local/lib/python3.6/site-packages/airflow/models/taskinstance.py", line 1455, in _execute_task_with_callbacks
    result = self._execute_task(context, self.task)
  File "/home/airflow/.local/lib/python3.6/site-packages/airflow/models/taskinstance.py", line 1511, in _execute_task
    result = execute_callable(context=context)
  File "/home/airflow/.local/lib/python3.6/site-packages/airflow/decorators/base.py", line 134, in execute
    return_value = super().execute(context)
  File "/home/airflow/.local/lib/python3.6/site-packages/airflow/operators/python.py", line 174, in execute
    return_value = self.execute_callable()
  File "/home/airflow/.local/lib/python3.6/site-packages/airflow/operators/python.py", line 185, in execute_callable
    return self.python_callable(*self.op_args, **self.op_kwargs)
  File "/opt/airflow/dags/load_dds_to_cdm.py", line 101, in populate_view_table
    cursor.execute(insert_query, {'age_group': row[0], 'user_count': row[1]})
  File "/home/airflow/.local/lib/python3.6/site-packages/vertica_python/vertica/cursor.py", line 238, in execute
    self._execute_simple_query(operation)
  File "/home/airflow/.local/lib/python3.6/site-packages/vertica_python/vertica/cursor.py", line 660, in _execute_simple_query
    raise errors.QueryError.from_error_response(self._message, query)
vertica_python.errors.QueryError: Severity: ERROR, Message: Invalid input syntax for integer: "0-17", Sqlstate: 22V02, Routine: scanint8, File: int8.c, Line: 124, Error Code: 3681, SQL: "             INSERT INTO dm.user_age_groups (age_group, user_count) VALUES (1, '0-17')         "
[2024-08-12 21:50:36,620] {local_task_job.py:154} INFO - Task exited with return code 1
[2024-08-12 21:50:36,658] {local_task_job.py:264} INFO - 0 downstream tasks scheduled from follow-on schedule check
